Workbook

Sheet processados
A1: cod_id | C1: endereco | D1: pasta_atual | E1: link_usado | F1: link_original_base | G1: check_box
A2: 1358664738 | B2: =_xlfn.XLOOKUP(A2,[1]links!$B:$B,[1]links!$A:$A) | C2: RUA CALIMERIO GUIMARAES 1485, 1485, DOUTOR PEDRO PEZZUTI | D2: BAIXA CONFIANCA - REVISAO | F2: https://www.google.com/maps/@?api=1&map_action=pano&viewpoint=-19.6017024583,-46.9317860959 | G2: FALSE
A3: 1496652853 | B3: =_xlfn.XLOOKUP(A3,[1]links!$B:$B,[1]links!$A:$A) | C3: RUA MARECHAL DEODORO 441, 441, CENTRO | D3: ESQUINA - REVISAO | F3: https://www.google.com/maps/@?api=1&map_action=pano&viewpoint=-19.5914561837,-46.9461888472 | G3: FALSE
A4: 1684853981 | B4: =_xlfn.XLOOKUP(A4,[1]links!$B:$B,[1]links!$A:$A) | C4: AVENIDA GETULIO VARGAS 675, 675, CENTRO | D4: POSTE UTILIZADO - REVISAO | F4: https://www.google.com/maps/@?api=1&map_action=pano&viewpoint=-19.5976348085,-46.9354733918 | G4: FALSE
A5: 219090082 | B5: =_xlfn.XLOOKUP(A5,[1]links!$B:$B,[1]links!$A:$A) | C5: RUA ANYSIO ROBERTO DA SILVA 140, 140, PRIMAVERAS | D5: POSTE UTILIZADO - REVISAO | E5: https://www.google.com/maps/@-19.6163418,-46.9260843,3a,74.1y,207.95h,107.71t/data=!3m7!1e1!3m5!1s9TJ1fGM0wHdkkJUHNvGoiw!2e0!6shttps:%2F%2Fstreetviewpixels-pa.clients6.google.com%2Fv1%2Fthumbnail%3Fcb_client%3Dmaps_sv.tactile%26w%3D900%26h%3D600%26pitch%3D-17.70742403609708%26panoid%3D9TJ1fGM0wHdkkJUHNvGoiw%26yaw%3D207.9531224695191!7i16384!8i8192?entry=ttu&g_ep=EgoyMDI2MDgxOS4wIKXMDSoASAFQAw%3D%3D | F5: https://www.google.com/maps/@?api=1&map_action=pano&viewpoint=-19.6163514809,-46.9262580622 | G5: TRUE | H5: =_xlfn.NUMBERVALUE(A5) | I5: =_xlfn.XLOOKUP(H5,Sheet1!A:A,Sheet1!B:B)
A6: 219090086 | B6: =_xlfn.XLOOKUP(A6,[1]links!$B:$B,[1]links!$A:$A) | C6: RUA EDSON APARECIDO DE SOUZA 235, 235, PRIMAVERAS | D6: POSTE UTILIZADO - OK | E6: https://www.google.com/maps/@-19.6171679,-46.9282077,3a,61.5y,233.82h,125.14t/data=!3m7!1e1!3m5!1snXIuk0AHrj2i41bmlfVk4g!2e0!6shttps:%2F%2Fstreetviewpixels-pa.clients6.google.com%2Fv1%2Fthumbnail%3Fcb_client%3Dmaps_sv.tactile%26w%3D900%26h%3D600%26pitch%3D-35.14448430046883%26panoid%3DnXIuk0AHrj2i41bmlfVk4g%26yaw%3D233.82494970398218!7i16384!8i8192?entry=ttu&g_ep=EgoyMDI2MDgxOS4wIKXMDSoASAFQAw%3D%3D | F6: https://www.google.com/maps/@?api=1&map_action=pano&viewpoint=-19.6172341862,-46.9281846528 | G6: TRUE | H6: =_xlfn.NUMBERVALUE(A6) | I6: =_xlfn.XLOOKUP(H6,Sheet1!A:A,Sheet1!B:B)
A7: 219298049 | B7: =_xlfn.XLOOKUP(A7,[1]links!$B:$B,[1]links!$A:$A) | C7: RUA MARECHAL DEODORO 375, 375, CENTRO | D7: BAIXA CONFIANCA - REVISAO | F7: https://www.google.com/maps/@?api=1&map_action=pano&viewpoint=-19.5914324748,-46.9469679704 | G7: FALSE
A8: 219298070 | B8: =_xlfn.XLOOKUP(A8,[1]links!$B:$B,[1]links!$A:$A) | C8: RUA GERALDA DETONI 56, 56, SANTA LUZIA | D8: POSTE UTILIZADO - REVISAO | E8: https://www.google.com/maps/@-19.5956345,-46.9467056,3a,75y,67.38h,112.74t/data=!3m7!1e1!3m5!1sMWSAit6qYADnp98bEZ_Fuw!2e0!6shttps:%2F%2Fstreetviewpixels-pa.googleapis.com%2Fv1%2Fthumbnail%3Fcb_client%3Dmaps_sv.tactile%26w%3D900%26h%3D600%26pitch%3D-22.742571625423054%26panoid%3DMWSAit6qYADnp98bEZ_Fuw%26yaw%3D67.3844637914525!7i16384!8i8192?entry=ttu | F8: https://www.google.com/maps/@?api=1&map_action=pano&viewpoint=-19.5956538529,-46.9466947042 | G8: TRUE | H8: =_xlfn.NUMBERVALUE(A8) | I8: =_xlfn.XLOOKUP(H8,Sheet1!A:A,Sheet1!B:B)
A9: 219298157 | B9: =_xlfn.XLOOKUP(A9,[1]links!$B:$B,[1]links!$A:$A) | C9: RUA JOAQUIM ANTONIO DUTRA 630, 630, CENTRO | D9: ESQUINA - OK | F9: https://www.google.com/maps/@?api=1&map_action=pano&viewpoint=-19.5914399797,-46.9462722863 | G9: FALSE
A10: 219298164 | B10: =_xlfn.XLOOKUP(A10,[1]links!$B:$B,[1]links!$A:$A) | C10: RUA GERALDA DETONI 545, 545, SANTA LUZIA | D10: ESQUINA - REVISAO | F10: https://www.google.com/maps/@?api=1&map_action=pano&viewpoint=-19.5997738451,-46.9466107983 | G10: FALSE
A11: 219298165 | B11: =_xlfn.XLOOKUP(A11,[1]links!$B:$B,[1]links!$A:$A) | C11: RUA MARCELINA CARDOSO 230, 230, SANTA LUZIA | D11: ESQUINA - REVISAO | F11: https://www.google.com/maps/@?api=1&map_action=pano&viewpoint=-19.5996249048,-46.9461801157 | G11: FALSE
A12: 219298197 | B12: =_xlfn.XLOOKUP(A12,[1]links!$B:$B,[1]links!$A:$A) | C12: RUA PAUL HARRIS 511, 511, JOAO RIBEIRO | D12: ESQUINA - REVISAO | F12: https://www.google.com/maps/@?api=1&map_action=pano&viewpoint=-19.6005603993,-46.9448760214 | G12: FALSE
A13: 219298202 | B13: =_xlfn.XLOOKUP(A13,[1]links!$B:$B,[1]links!$A:$A) | C13: RUA FUNCIONARIO JOAO ROSA 125, 125, CENTRO | D13: ESQUINA - REVISAO | F13: https://www.google.com/maps/@?api=1&map_action=pano&viewpoint=-19.5939088732,-46.945167775 | G13: FALSE
A14: 219298203 | B14: =_xlfn.XLOOKUP(A14,[1]links!$B:$B,[1]links!$A:$A) | C14: TRAVESSA DEZ 295, 295, CENTRO | D14: ESQUINA - REVISAO | F14: https://www.google.com/maps/@?api=1&map_action=pano&viewpoint=-19.5953479045,-46.9449086398 | G14: FALSE
A15: 219298247 | B15: =_xlfn.XLOOKUP(A15,[1]links!$B:$B,[1]links!$A:$A) | C15: AVENIDA IMBIARA 754, 754, JOAO RIBEIRO | D15: ESQUINA - REVISAO | F15: https://www.google.com/maps/@?api=1&map_action=pano&viewpoint=-19.6003193604,-46.9404218493 | G15: FALSE
A16: 219298278 | B16: =_xlfn.XLOOKUP(A16,[1]links!$B:$B,[1]links!$A:$A) | C16: AVENIDA PREFEITO ARACELY DE PAULA 1514, 1514, CENTRO | D16: BAIXA CONFIANCA - REVISAO | F16: https://www.google.com/maps/@?api=1&map_action=pano&viewpoint=-19.5982713064,-46.9418651389 | G16: FALSE
A17: 219298283 | B17: =_xlfn.XLOOKUP(A17,[1]links!$B:$B,[1]links!$A:$A) | C17: RUA HEITOR MONTANDON 113, 113, CENTRO | D17: ESQUINA - REVISAO | F17: https://www.google.com/maps/@?api=1&map_action=pano&viewpoint=-19.5973238041,-46.9417775125 | G17: FALSE
A18: 219298314 | B18: =_xlfn.XLOOKUP(A18,[1]links!$B:$B,[1]links!$A:$A) | C18: RUA ANTONIO ALVES DA COSTA 65, 65, SAO PEDRO | D18: POSTE UTILIZADO - REVISAO | E18: https://www.google.com/maps/@-19.58464,-46.941685,3a,90y,25.2h,121.71t/data=!3m7!1e1!3m5!1s4C2AkXGEw4tlbx4LO5i_Xg!2e0!6shttps:%2F%2Fstreetviewpixels-pa.googleapis.com%2Fv1%2Fthumbnail%3Fcb_client%3Dmaps_sv.tactile%26w%3D900%26h%3D600%26pitch%3D-31.714880004781662%26panoid%3D4C2AkXGEw4tlbx4LO5i_Xg%26yaw%3D25.199742245425014!7i16384!8i8192?entry=ttu&g_ep=EgoyMDI2MDgxOS4wIKXMDSoASAFQAw%3D%3D | F18: https://www.google.com/maps/@?api=1&map_action=pano&viewpoint=-19.5846055755,-46.9417488295 | G18: FALSE | H18: =_xlfn.NUMBERVALUE(A18) | I18: =_xlfn.XLOOKUP(H18,Sheet1!A:A,Sheet1!B:B)
A19: 219298767 | B19: =_xlfn.XLOOKUP(A19,[1]links!$B:$B,[1]links!$A:$A) | C19: RUA JOSE CARLOS PEDRO GRANDE 1195, 1195, ADHEMAR RODRIGUES VALLE | D19: POSTE UTILIZADO - REVISAO | E19: https://www.google.com/maps/@-19.6144908,-46.9251863,3a,48.9y,359.13h,109.25t/data=!3m7!1e1!3m5!1s5B1vAq3ChEm5n-4T_NLXkg!2e0!6shttps:%2F%2Fstreetviewpixels-pa.clients6.google.com%2Fv1%2Fthumbnail%3Fcb_client%3Dmaps_sv.tactile%26w%3D900%26h%3D600%26pitch%3D-19.25125269409142%26panoid%3D5B1vAq3ChEm5n-4T_NLXkg%26yaw%3D359.1259169366337!7i16384!8i8192?entry=ttu&g_ep=EgoyMDI2MDgxOS4wIKXMDSoASAFQAw%3D%3D | F19: https://www.google.com/maps/@?api=1&map_action=pano&viewpoint=-19.6143936344,-46.925195675 | G19: FALSE | H19: =_xlfn.NUMBERVALUE(A19) | I19: =_xlfn.XLOOKUP(H19,Sheet1!A:A,Sheet1!B:B)
A20: 219298786 | B20: =_xlfn.XLOOKUP(A20,[1]links!$B:$B,[1]links!$A:$A) | C20: RUA GUIMARAES ROSA 105, 105, PRIMAVERAS | D20: POSTE UTILIZADO - REVISAO | E20: https://www.google.com/maps/@-19.615895,-46.9259955,3a,75y,19.48h,120.47t/data=!3m7!1e1!3m5!1sxd0pnLIC6Q-VTGUxIyijTQ!2e0!6shttps:%2F%2Fstreetviewpixels-pa.clients6.google.com%2Fv1%2Fthumbnail%3Fcb_client%3Dmaps_sv.tactile%26w%3D900%26h%3D600%26pitch%3D-30.47128022330449%26panoid%3Dxd0pnLIC6Q-VTGUxIyijTQ%26yaw%3D19.475669072115974!7i16384!8i8192?entry=ttu&g_ep=EgoyMDI2MDgxOS4wIKXMDSoASAFQAw%3D%3D | F20: https://www.google.com/maps/@?api=1&map_action=pano&viewpoint=-19.6158757818,-46.9259759044 | G20: FALSE | H20: =_xlfn.NUMBERVALUE(A20) | I20: =_xlfn.XLOOKUP(H20,Sheet1!A:A,Sheet1!B:B)
A21: 219298788 | B21: =_xlfn.XLOOKUP(A21,[1]links!$B:$B,[1]links!$A:$A) | C21: RUA AFONSO PENA 40, 40, PRIMAVERAS | D21: POSTE UTILIZADO - REVISAO | E21: https://www.google.com/maps/@-19.6161963,-46.925153,3a,46.9y,120.37h,119.11t/data=!3m7!1e1!3m5!1sRJbLeFTXDWMG7IgYLdQWkw!2e0!6shttps:%2F%2Fstreetviewpixels-pa.clients6.google.com%2Fv1%2Fthumbnail%3Fcb_client%3Dmaps_sv.tactile%26w%3D900%26h%3D600%26pitch%3D-29.108450476188423%26panoid%3DRJbLeFTXDWMG7IgYLdQWkw%26yaw%3D120.37277416999979!7i16384!8i8192?entry=ttu&g_ep=EgoyMDI2MDgxOS4wIKXMDSoASAFQAw%3D%3D | F21: https://www.google.com/maps/@?api=1&map_action=pano&viewpoint=-19.6162280814,-46.9251316784 | G21: FALSE | H21: =_xlfn.NUMBERVALUE(A21) | I21: =_xlfn.XLOOKUP(H21,Sheet1!A:A,Sheet1!B:B)
A22: 219298798 | B22: =_xlfn.XLOOKUP(A22,[1]links!$B:$B,[1]links!$A:$A) | C22: RUA JOSE CARLOS PEDRO GRANDE 1265, 1265, ADHEMAR RODRIGUES VALLE | D22: POSTE UTILIZADO - REVISAO | E22: https://www.google.com/maps/@-19.6149482,-46.9250697,3a,75y,103.03h,117.64t/data=!3m7!1e1!3m5!1sdnt_ZTrbW3gq0tZc7enuMg!2e0!6shttps:%2F%2Fstreetviewpixels-pa.clients6.google.com%2Fv1%2Fthumbnail%3Fcb_client%3Dmaps_sv.tactile%26w%3D900%26h%3D600%26pitch%3D-27.640093323522493%26panoid%3Ddnt_ZTrbW3gq0tZc7enuMg%26yaw%3D103.03250289548745!7i16384!8i8192?entry=ttu&g_ep=EgoyMDI2MDgxOS4wIKXMDSoASAFQAw%3D%3D | F22: https://www.google.com/maps/@?api=1&map_action=pano&viewpoint=-19.614946355,-46.9250402101 | G22: FALSE | H22: =_xlfn.NUMBERVALUE(A22) | I22: =_xlfn.XLOOKUP(H22,Sheet1!A:A,Sheet1!B:B)
A23: 219384929 | B23: =_xlfn.XLOOKUP(A23,[1]links!$B:$B,[1]links!$A:$A) | C23: AVENIDA GETULIO VARGAS 336, 336, CENTRO | D23: POSTE UTILIZADO - REVISAO | E23: https://www.google.com/maps/@-19.5955996,-46.9380826,3a,41.2y,301.39h,100.37t/data=!3m7!1e1!3m5!1s9xwhCkqXMCt6Uja2PNBsYw!2e0!6shttps:%2F%2Fstreetviewpixels-pa.clients6.google.com%2Fv1%2Fthumbnail%3Fcb_client%3Dmaps_sv.tactile%26w%3D900%26h%3D600%26pitch%3D-10.370894170244398%26panoid%3D9xwhCkqXMCt6Uja2PNBsYw%26yaw%3D301.39068199510353!7i16384!8i8192?entry=ttu | F23: https://www.google.com/maps/@?api=1&map_action=pano&viewpoint=-19.5955824827,-46.9382299559 | G23: FALSE | H23: =_xlfn.NUMBERVALUE(A23) | I23: =_xlfn.XLOOKUP(H23,Sheet1!A:A,Sheet1!B:B)
A24: 219384968 | B24: =_xlfn.XLOOKUP(A24,[1]links!$B:$B,[1]links!$A:$A) | C24: RUA FRANCISCO PORFIRIO 2, 2, CENTRO | D24: ESQUINA - REVISAO | E24: https://www.google.com/maps/@-19.5861668,-46.9354116,3a,48.9y,70.42h,114.78t/data=!3m7!1e1!3m5!1sflZLjn_1ddl-6PsBSbThnQ!2e0!6shttps:%2F%2Fstreetviewpixels-pa.googleapis.com%2Fv1%2Fthumbnail%3Fcb_client%3Dmaps_sv.tactile%26w%3D900%26h%3D600%26pitch%3D-24.782833498956876%26panoid%3DflZLjn_1ddl-6PsBSbThnQ%26yaw%3D70.42051318060854!7i16384!8i8192?entry=ttu&g_ep=EgoyMDI2MDgxOS4wIKXMDSoASAFQAw%3D%3D | F24: https://www.google.com/maps/@?api=1&map_action=pano&viewpoint=-19.5861464766,-46.9353816591 | G24: FALSE | H24: =_xlfn.NUMBERVALUE(A24) | I24: =_xlfn.XLOOKUP(H24,Sheet1!A:A,Sheet1!B:B)
A25: 219384971 | B25: =_xlfn.XLOOKUP(A25,[1]links!$B:$B,[1]links!$A:$A) | C25: RUA TIA NICA 327, 327, RICA | D25: POSTE UTILIZADO - REVISAO | E25: https://www.google.com/maps/@-19.5854858,-46.9369094,3a,46.9y,17.06h,110.23t/data=!3m7!1e1!3m5!1sajjlgtmQKWwB0mEIaQObGA!2e0!6shttps:%2F%2Fstreetviewpixels-pa.googleapis.com%2Fv1%2Fthumbnail%3Fcb_client%3Dmaps_sv.tactile%26w%3D900%26h%3D600%26pitch%3D-20.227120820408686%26panoid%3DajjlgtmQKWwB0mEIaQObGA%26yaw%3D17.05920716028874!7i16384!8i8192?entry=ttu&g_ep=EgoyMDI2MDgxOS4wIKXMDSoASAFQAw%3D%3D | F25: https://www.google.com/maps/@?api=1&map_action=pano&viewpoint=-19.5854435089,-46.9369077016 | G25: FALSE | H25: =_xlfn.NUMBERVALUE(A25) | I25: =_xlfn.XLOOKUP(H25,Sheet1!A:A,Sheet1!B:B)
A26: 219385014 | B26: =_xlfn.XLOOKUP(A26,[1]links!$B:$B,[1]links!$A:$A) | C26: RUA ANTONIO ALVES DA COSTA 201, 201, RICA | D26: POSTE UTILIZADO - REVISAO | E26: https://www.google.com/maps/@-19.5852886,-46.9375621,3a,39.4y,284.8h,105.61t/data=!3m7!1e1!3m5!1sUthlppVTp1qITTgStoHDFA!2e0!6shttps:%2F%2Fstreetviewpixels-pa.googleapis.com%2Fv1%2Fthumbnail%3Fcb_client%3Dmaps_sv.tactile%26w%3D900%26h%3D600%26pitch%3D-15.610240223663695%26panoid%3DUthlppVTp1qITTgStoHDFA%26yaw%3D284.79934053384784!7i16384!8i8192?entry=ttu&g_ep=EgoyMDI2MDgxOS4wIKXMDSoASAFQAw%3D%3D | F26: https://www.google.com/maps/@?api=1&map_action=pano&viewpoint=-19.5852816112,-46.9376873419 | G26: FALSE | H26: =_xlfn.NUMBERVALUE(A26) | I26: =_xlfn.XLOOKUP(H26,Sheet1!A:A,Sheet1!B:B)
A27: 219385242 | B27: =_xlfn.XLOOKUP(A27,[1]links!$B:$B,[1]links!$A:$A) | C27: RUA SALOMAO PEREIRA DE MESQUITA 179, 179, CENTRO | D27: POSTE UTILIZADO - REVISAO | E27: https://www.google.com/maps/@-19.5868647,-46.9352957,3a,37.6y,126.25h,107.49t/data=!3m7!1e1!3m5!1sIzKvPw7zg45LW7MsHWIRiQ!2e0!6shttps:%2F%2Fstreetviewpixels-pa.googleapis.com%2Fv1%2Fthumbnail%3Fcb_client%3Dmaps_sv.tactile%26w%3D900%26h%3D600%26pitch%3D-17.485805539088418%26panoid%3DIzKvPw7zg45LW7MsHWIRiQ%26yaw%3D126.25343324785146!7i16384!8i8192?entry=ttu&g_ep=EgoyMDI2MDgxOS4wIKXMDSoASAFQAw%3D%3D | F27: https://www.google.com/maps/@?api=1&map_action=pano&viewpoint=-19.5869062985,-46.9352858813 | G27: FALSE | H27: =_xlfn.NUMBERVALUE(A27) | I27: =_xlfn.XLOOKUP(H27,Sheet1!A:A,Sheet1!B:B)
A28: 219385251 | B28: =_xlfn.XLOOKUP(A28,[1]links!$B:$B,[1]links!$A:$A) | C28: RUA ANTONIO LACERDA 74, 74, CENTRO | D28: POSTE UTILIZADO - REVISAO | E28: https://www.google.com/maps/@-19.5867291,-46.9346974,3a,75y,359.79h,108.91t/data=!3m7!1e1!3m5!1s2G_e4-QUx19PKg51EmPCVQ!2e0!6shttps:%2F%2Fstreetviewpixels-pa.googleapis.com%2Fv1%2Fthumbnail%3Fcb_client%3Dmaps_sv.tactile%26w%3D900%26h%3D600%26pitch%3D-18.909215927281252%26panoid%3D2G_e4-QUx19PKg51EmPCVQ%26yaw%3D359.78562035818476!7i16384!8i8192?entry=ttu&g_ep=EgoyMDI2MDgxOS4wIKXMDSoASAFQAw%3D%3D | F28: https://www.google.com/maps/@?api=1&map_action=pano&viewpoint=-19.5866682452,-46.9347398247 | G28: FALSE | H28: =_xlfn.NUMBERVALUE(A28) | I28: =_xlfn.XLOOKUP(H28,Sheet1!A:A,Sheet1!B:B)
A29: 219386635 | B29: =_xlfn.XLOOKUP(A29,[1]links!$B:$B,[1]links!$A:$A) | C29: AVENIDA JOAO PAULO II 0, 0, SAO PEDRO | D29: POSTE UTILIZADO - REVISAO | E29: https://www.google.com/maps/@-19.583433,-46.943135,3a,48.9y,61.52h,109.98t/data=!3m7!1e1!3m5!1sDoJ0z_e3JnOtcDM8wmRgXQ!2e0!6shttps:%2F%2Fstreetviewpixels-pa.googleapis.com%2Fv1%2Fthumbnail%3Fcb_client%3Dmaps_sv.tactile%26w%3D900%26h%3D600%26pitch%3D-19.983115485543564%26panoid%3DDoJ0z_e3JnOtcDM8wmRgXQ%26yaw%3D61.520243494085356!7i16384!8i8192?entry=ttu&g_ep=EgoyMDI2MDgxOS4wIKXMDSoASAFQAw%3D%3D | F29: https://www.google.com/maps/@?api=1&map_action=pano&viewpoint=-19.583380751,-46.9430875064 | G29: FALSE | H29: =_xlfn.NUMBERVALUE(A29) | I29: =_xlfn.XLOOKUP(H29,Sheet1!A:A,Sheet1!B:B)
... A53: 219992818 | B53: =_xlfn.XLOOKUP(A53,[1]links!$B:$B,[1]links!$A:$A) | C53: RUA SALOMAO PEREIRA DE MESQUITA 93, 93, CENTRO | D53: POSTE UTILIZADO - OK | E53: https://www.google.com/maps/@-19.5876763,-46.9346634,3a,75y,96.91h,128.07t/data=!3m7!1e1!3m5!1sGuo2tlt4blXpeRarqmpdzg!2e0!6shttps:%2F%2Fstreetviewpixels-pa.googleapis.com%2Fv1%2Fthumbnail%3Fcb_client%3Dmaps_sv.tactile%26w%3D900%26h%3D600%26pitch%3D-38.06733212300182%26panoid%3DGuo2tlt4blXpeRarqmpdzg%26yaw%3D96.90968014838509!7i16384!8i8192?entry=ttu&g_ep=EgoyMDI2MDgxOS4wIKXMDSoASAFQAw%3D%3D | F53: https://www.google.com/maps/@?api=1&map_action=pano&viewpoint=-19.5876714804,-46.9346851063 | G53: FALSE | H53: =_xlfn.NUMBERVALUE(A53) | I53: =_xlfn.XLOOKUP(H53,Sheet1!A:A,Sheet1!B:B)
A54: 219993025 | B54: =_xlfn.XLOOKUP(A55,[1]links!$B:$B,[1]links!$A:$A) | C54: RUA ANTONIO ALVES DA COSTA 161, 161, SAO PEDRO | D54: POSTE UTILIZADO - REVISAO | E54: https://www.google.com/maps/@-19.5847945,-46.9382762,3a,44.9y,145.39h,117.42t/data=!3m7!1e1!3m5!1syscUs8mcvfnEvfQke1l7Sg!2e0!6shttps:%2F%2Fstreetviewpixels-pa.googleapis.com%2Fv1%2Fthumbnail%3Fcb_client%3Dmaps_sv.tactile%26w%3D900%26h%3D600%26pitch%3D-27.419908741191918%26panoid%3DyscUs8mcvfnEvfQke1l7Sg%26yaw%3D145.39159609328667!7i16384!8i8192?entry=ttu&g_ep=EgoyMDI2MDgxOS4wIKXMDSoASAFQAw%3D%3D | F54: https://www.google.com/maps/@?api=1&map_action=pano&viewpoint=-19.5848415135,-46.9382920388 | G54: FALSE | H54: =_xlfn.NUMBERVALUE(A55) | I54: =_xlfn.XLOOKUP(H55,Sheet1!A:A,Sheet1!B:B)
A55: 219993026 | B55: =_xlfn.XLOOKUP(A56,[1]links!$B:$B,[1]links!$A:$A) | C55: RUA CLARIMUNDO BATISTA DA COSTA 74, 74, SAO PEDRO | D55: POSTE UTILIZADO - REVISAO | E55: https://www.google.com/maps/@-19.5846281,-46.937535,3a,48.9y,344.96h,111.25t/data=!3m7!1e1!3m5!1saT6dgtg3EUIKBW_ggE_zOw!2e0!6shttps:%2F%2Fstreetviewpixels-pa.googleapis.com%2Fv1%2Fthumbnail%3Fcb_client%3Dmaps_sv.tactile%26w%3D900%26h%3D600%26pitch%3D-21.246557159906004%26panoid%3DaT6dgtg3EUIKBW_ggE_zOw%26yaw%3D344.963899250288!7i16384!8i8192?entry=ttu&g_ep=EgoyMDI2MDgxOS4wIKXMDSoASAFQAw%3D%3D | F55: https://www.google.com/maps/@?api=1&map_action=pano&viewpoint=-19.5845960661,-46.9375933466 | G55: FALSE | H55: =_xlfn.NUMBERVALUE(A56) | I55: =_xlfn.XLOOKUP(H56,Sheet1!A:A,Sheet1!B:B)
A56: 220081179 | B56: =_xlfn.XLOOKUP(A57,[1]links!$B:$B,[1]links!$A:$A) | C56: RUA EDSON APARECIDO DE SOUZA 105, 105, PRIMAVERAS | D56: POSTE UTILIZADO - REVISAO | E56: https://www.google.com/maps/@-19.6171497,-46.9297902,3a,75y,13.05h,125.85t/data=!3m7!1e1!3m5!1siEBlSZjng0NsRJ5xrXeIJQ!2e0!6shttps:%2F%2Fstreetviewpixels-pa.clients6.google.com%2Fv1%2Fthumbnail%3Fcb_client%3Dmaps_sv.tactile%26w%3D900%26h%3D600%26pitch%3D-35.84787951718599%26panoid%3DiEBlSZjng0NsRJ5xrXeIJQ%26yaw%3D13.053494475463442!7i16384!8i8192?entry=ttu&g_ep=EgoyMDI2MDgxOS4wIKXMDSoASAFQAw%3D%3D | F56: https://www.google.com/maps/@?api=1&map_action=pano&viewpoint=-19.6171361934,-46.9297468606 | G56: FALSE | H56: =_xlfn.NUMBERVALUE(A57) | I56: =_xlfn.XLOOKUP(H57,Sheet1!A:A,Sheet1!B:B)
A57: 220081181 | B57: =_xlfn.XLOOKUP(A58,[1]links!$B:$B,[1]links!$A:$A) | C57: RUA MARIA DE LOURDES DE JESUS 125, 125, PRIMAVERAS | D57: POSTE UTILIZADO - REVISAO | E57: https://www.google.com/maps/@-19.6168501,-46.9264632,3a,90y,359.15h,109.51t/data=!3m7!1e1!3m5!1sjN75oI15nVUC6SU5wOE19w!2e0!6shttps:%2F%2Fstreetviewpixels-pa.clients6.google.com%2Fv1%2Fthumbnail%3Fcb_client%3Dmaps_sv.tactile%26w%3D900%26h%3D600%26pitch%3D-19.51393587423064%26panoid%3DjN75oI15nVUC6SU5wOE19w%26yaw%3D359.15178274749564!7i16384!8i8192?entry=ttu&g_ep=EgoyMDI2MDgxOS4wIKXMDSoASAFQAw%3D%3D | F57: https://www.google.com/maps/@?api=1&map_action=pano&viewpoint=-19.6167919041,-46.9264634403 | G57: FALSE | H57: =_xlfn.NUMBERVALUE(A58) | I57: =_xlfn.XLOOKUP(H58,Sheet1!A:A,Sheet1!B:B)
A58: 220081185 | B58: =_xlfn.XLOOKUP(A59,[1]links!$B:$B,[1]links!$A:$A) | C58: RUA VEREADOR JOSE ROSINHA 210, 210, PRIMAVERAS | D58: POSTE UTILIZADO - REVISAO | E58: https://www.google.com/maps/@-19.6165752,-46.9285848,3a,75y,3.31h,121.54t/data=!3m7!1e1!3m5!1s8wN9KjA3eRdW29fyNCJCOg!2e0!6shttps:%2F%2Fstreetviewpixels-pa.clients6.google.com%2Fv1%2Fthumbnail%3Fcb_client%3Dmaps_sv.tactile%26w%3D900%26h%3D600%26pitch%3D-31.53889944565141%26panoid%3D8wN9KjA3eRdW29fyNCJCOg%26yaw%3D3.3149581532608186!7i16384!8i8192?entry=ttu&g_ep=EgoyMDI2MDgxOS4wIKXMDSoASAFQAw%3D%3D | F58: https://www.google.com/maps/@?api=1&map_action=pano&viewpoint=-19.616561648,-46.9285674519 | G58: FALSE | H58: =_xlfn.NUMBERVALUE(A59) | I58: =_xlfn.XLOOKUP(H59,Sheet1!A:A,Sheet1!B:B)
A59: 220247378 | B59: =_xlfn.XLOOKUP(A60,[1]links!$B:$B,[1]links!$A:$A) | C59: RUA FRANCISCO PORFIRIO 346, 346, SAO PEDRO | D59: POSTE UTILIZADO - REVISAO | E59: https://www.google.com/maps/@-19.5838499,-46.9381458,3a,51y,42.71h,108.99t/data=!3m8!1e1!3m6!1sQbK4P991CktxHToUz5BZiQ!2e0!5s20110801T000000!6shttps:%2F%2Fstreetviewpixels-pa.googleapis.com%2Fv1%2Fthumbnail%3Fcb_client%3Dmaps_sv.tactile%26w%3D900%26h%3D600%26pitch%3D-18.986675086723025%26panoid%3DQbK4P991CktxHToUz5BZiQ%26yaw%3D42.705058973114404!7i13312!8i6656?entry=ttu&g_ep=EgoyMDI2MDgxOS4wIKXMDSoASAFQAw%3D%3D | F59: https://www.google.com/maps/@?api=1&map_action=pano&viewpoint=-19.5837684074,-46.9381266544 | G59: FALSE | H59: =_xlfn.NUMBERVALUE(A60) | I59: =_xlfn.XLOOKUP(H60,Sheet1!A:A,Sheet1!B:B)
A60: 220247379 | B60: =_xlfn.XLOOKUP(A61,[1]links!$B:$B,[1]links!$A:$A) | C60: AVENIDA DAMASO DRUMMOND 2615, 2615, SAO PEDRO | D60: POSTE UTILIZADO - REVISAO | E60: https://www.google.com/maps/@-19.5824416,-46.9416179,3a,48.9y,69.54h,107.46t/data=!3m8!1e1!3m6!1sfohNC-14VbaRmf7d_OoYng!2e0!5s20210901T000000!6shttps:%2F%2Fstreetviewpixels-pa.googleapis.com%2Fv1%2Fthumbnail%3Fcb_client%3Dmaps_sv.tactile%26w%3D900%26h%3D600%26pitch%3D-17.464480419366126%26panoid%3DfohNC-14VbaRmf7d_OoYng%26yaw%3D69.54340259051868!7i16384!8i8192?entry=ttu&g_ep=EgoyMDI2MDgxOS4wIKXMDSoASAFQAw%3D%3D | F60: https://www.google.com/maps/@?api=1&map_action=pano&viewpoint=-19.5824052726,-46.9413984384 | G60: FALSE | H60: =_xlfn.NUMBERVALUE(A61) | I60: =_xlfn.XLOOKUP(H61,Sheet1!A:A,Sheet1!B:B)
A61: 220247385 | B61: =_xlfn.XLOOKUP(A62,[1]links!$B:$B,[1]links!$A:$A) | C61: AVENIDA DAMASO DRUMMOND 1385, 1385, CENTRO | D61: POSTE UTILIZADO - REVISAO | E61: https://www.google.com/maps/@-19.5870978,-46.9337663,3a,75y,303.27h,130.02t/data=!3m7!1e1!3m5!1sVk5FRYE2ufDCIVtTzI3TOA!2e0!6shttps:%2F%2Fstreetviewpixels-pa.googleapis.com%2Fv1%2Fthumbnail%3Fcb_client%3Dmaps_sv.tactile%26w%3D900%26h%3D600%26pitch%3D-40.01700076162919%26panoid%3DVk5FRYE2ufDCIVtTzI3TOA%26yaw%3D303.27431080876124!7i16384!8i8192?entry=ttu&g_ep=EgoyMDI2MDgxOS4wIKXMDSoASAFQAw%3D%3D | F61: https://www.google.com/maps/@?api=1&map_action=pano&viewpoint=-19.5870755491,-46.9338201932 | G61: TRUE | H61: =_xlfn.NUMBERVALUE(A62) | I61: =_xlfn.XLOOKUP(H62,Sheet1!A:A,Sheet1!B:B)
A62: 220247386 | B62: =_xlfn.XLOOKUP(A63,[1]links!$B:$B,[1]links!$A:$A) | C62: AVENIDA DAMASO DRUMMOND 1395, 1395, CENTRO | D62: ESQUINA - REVISAO | E62: https://www.google.com/maps/@-19.5869158,-46.9337676,3a,39.4y,331.23h,108.71t/data=!3m7!1e1!3m5!1sb5qdNWb9Xba95aCaxis94A!2e0!6shttps:%2F%2Fstreetviewpixels-pa.googleapis.com%2Fv1%2Fthumbnail%3Fcb_client%3Dmaps_sv.tactile%26w%3D900%26h%3D600%26pitch%3D-18.708551664728702%26panoid%3Db5qdNWb9Xba95aCaxis94A%26yaw%3D331.23101974879216!7i16384!8i8192?entry=ttu&g_ep=EgoyMDI2MDgxOS4wIKXMDSoASAFQAw%3D%3D | F62: https://www.google.com/maps/@?api=1&map_action=pano&viewpoint=-19.5868405976,-46.9338269013 | G62: FALSE | H62: =_xlfn.NUMBERVALUE(A63) | I62: =_xlfn.XLOOKUP(H63,Sheet1!A:A,Sheet1!B:B)
A63: 220247480 | B63: =_xlfn.XLOOKUP(A64,[1]links!$B:$B,[1]links!$A:$A) | C63: AVENIDA JOAO PAULO II 0, 0, SAO PEDRO | D63: POSTE UTILIZADO - REVISAO | E63: https://www.google.com/maps/@-19.5830214,-46.9427703,3a,90y,92.32h,118.12t/data=!3m7!1e1!3m5!1sF1kx9bhfyCrt9Kk5ECxSXA!2e0!6shttps:%2F%2Fstreetviewpixels-pa.googleapis.com%2Fv1%2Fthumbnail%3Fcb_client%3Dmaps_sv.tactile%26w%3D900%26h%3D600%26pitch%3D-28.115626557753743%26panoid%3DF1kx9bhfyCrt9Kk5ECxSXA%26yaw%3D92.31502670330299!7i16384!8i8192?entry=ttu&g_ep=EgoyMDI2MDgxOS4wIKXMDSoASAFQAw%3D%3D | F63: https://www.google.com/maps/@?api=1&map_action=pano&viewpoint=-19.5829871429,-46.9427301005 | G63: FALSE | H63: =_xlfn.NUMBERVALUE(A64) | I63: =_xlfn.XLOOKUP(H64,Sheet1!A:A,Sheet1!B:B)
...

Sheet Sheet2

Sheet Sheet1
A1: 219090082 | B1: =_xlfn.XLOOKUP(A1,[2]lista_postes!$P:$P,[2]lista_postes!$AX:$AX)
A2: 219090086 | B2: =_xlfn.XLOOKUP(A2,[2]lista_postes!$P:$P,[2]lista_postes!$AX:$AX)
A3: 219298070 | B3: =_xlfn.XLOOKUP(A3,[2]lista_postes!$P:$P,[2]lista_postes!$AX:$AX)
A4: 219298314 | B4: =_xlfn.XLOOKUP(A4,[2]lista_postes!$P:$P,[2]lista_postes!$AX:$AX)
A5: 219298767 | B5: =_xlfn.XLOOKUP(A5,[2]lista_postes!$P:$P,[2]lista_postes!$AX:$AX)
A6: 219298786 | B6: =_xlfn.XLOOKUP(A6,[2]lista_postes!$P:$P,[2]lista_postes!$AX:$AX)
A7: 219298788 | B7: =_xlfn.XLOOKUP(A7,[2]lista_postes!$P:$P,[2]lista_postes!$AX:$AX)
A8: 219298798 | B8: =_xlfn.XLOOKUP(A8,[2]lista_postes!$P:$P,[2]lista_postes!$AX:$AX)
A9: 219384929 | B9: =_xlfn.XLOOKUP(A9,[2]lista_postes!$P:$P,[2]lista_postes!$AX:$AX)
A10: 219384968 | B10: =_xlfn.XLOOKUP(A10,[2]lista_postes!$P:$P,[2]lista_postes!$AX:$AX)
A11: 219384971 | B11: =_xlfn.XLOOKUP(A11,[2]lista_postes!$P:$P,[2]lista_postes!$AX:$AX)
A12: 219385014 | B12: =_xlfn.XLOOKUP(A12,[2]lista_postes!$P:$P,[2]lista_postes!$AX:$AX)
... A218: 350236676 | B218: =_xlfn.XLOOKUP(A218,[2]lista_postes!$P:$P,[2]lista_postes!$AX:$AX)
